[2023-02-03 13:52:09 DEBUG] [cli:115] ###############################################################################
[2023-02-03 13:52:09 DEBUG] [cli:116] Running command 'run'
[2023-02-03 13:52:09 DEBUG] [cli:120] Using settings file '/home/runner/.chaostoolkit/settings.yaml'
[2023-02-03 13:52:09 DEBUG] [settings:30] The Chaos Toolkit settings file could not be found at '/home/runner/.chaostoolkit/settings.yaml'.
[2023-02-03 13:52:09 DEBUG] [__init__:449] No controls to apply on 'loader'
[2023-02-03 13:52:10 DEBUG] [loader:129] Fetched experiment: 
    {"title":"List cloud run instances","method":[{"name":"list-cloudrun-instances","type":"probe","provider":{"func":"list_services","type":"python","module":"chaosgcp.cloudrun.probes","arguments":{"parent":"projects/reliably-staging-project/locations/europe-west1"}}}],"version":"1.0.0","controls":[{"name":"reliably","provider":{"type":"python","module":"chaosreliably.controls.experiment","arguments":{"exp_id":"4556a14b-e776-4cd1-a6b1-c320e06bde2c","org_id":"8f67bb6a-4944-40af-80b0-921023467cdc"}}}],"description":"n/a","contributions":{"security":"none","performance":"none","availability":"none"}}
[2023-02-03 13:52:10 DEBUG] [__init__:449] No controls to apply on 'loader'
[2023-02-03 13:52:10 DEBUG] [caching:24] Building activity cache...
[2023-02-03 13:52:10 DEBUG] [caching:35] Cached 1 activities
[2023-02-03 13:52:10 INFO] [experiment:58] Validating the experiment's syntax
[2023-02-03 13:52:10 DEBUG] [configuration:63] Loading configuration...
[2023-02-03 13:52:10 DEBUG] [secret:78] Loading secrets...
[2023-02-03 13:52:10 DEBUG] [secret:104] Done loading secrets
[2023-02-03 13:52:10 DEBUG] [python:192] Control module '/opt/hostedtoolcache/Python/3.10.9/x64/lib/python3.10/site-packages/chaosreliably/controls/experiment.py' does not declare 'validate_control'
[2023-02-03 13:52:10 INFO] [experiment:109] Experiment looks valid
[2023-02-03 13:52:10 DEBUG] [caching:42] Clearing activities cache
[2023-02-03 13:52:10 DEBUG] [cli:314] Runtime strategies: hypothesis - default / rollbacks - always
[2023-02-03 13:52:10 DEBUG] [caching:24] Building activity cache...
[2023-02-03 13:52:10 DEBUG] [caching:35] Cached 1 activities
[2023-02-03 13:52:10 DEBUG] [configuration:63] Loading configuration...
[2023-02-03 13:52:10 DEBUG] [secret:78] Loading secrets...
[2023-02-03 13:52:10 DEBUG] [secret:104] Done loading secrets
[2023-02-03 13:52:10 DEBUG] [configuration:160] Loading dynamic configuration...
[2023-02-03 13:52:10 INFO] [run:370] Running experiment: List cloud run instances
[2023-02-03 13:52:10 DEBUG] [__init__:64] Initializing controls
[2023-02-03 13:52:10 DEBUG] [__init__:73] Initializing control 'reliably'
[2023-02-03 13:52:10 DEBUG] [python:196] Control 'configure_control' loaded from '/opt/hostedtoolcache/Python/3.10.9/x64/lib/python3.10/site-packages/chaosreliably/controls/experiment.py'
[2023-02-03 13:52:10 DEBUG] [experiment:402] Configure Reliably's experiment control
[2023-02-03 13:52:11 INFO] [experiment:188] Reliably execution: 3ea37a66-be45-4245-9dc6-26c1bf55a2d2
[2023-02-03 13:52:11 DEBUG] [experiment:74] Starting Reliably state checker now
[2023-02-03 13:52:11 INFO] [run:397] Steady-state strategy: default
[2023-02-03 13:52:11 INFO] [run:401] Rollbacks strategy: always
[2023-02-03 13:52:11 INFO] [run:406] No steady state hypothesis defined. That's ok, just exploring.
[2023-02-03 13:52:11 DEBUG] [__init__:459] Applying before-control 'reliably' on 'experiment'
[2023-02-03 13:52:11 DEBUG] [python:192] Control module '/opt/hostedtoolcache/Python/3.10.9/x64/lib/python3.10/site-packages/chaosreliably/controls/experiment.py' does not declare 'before_experiment_control'
[2023-02-03 13:52:11 INFO] [run:664] Playing your experiment's method now...
[2023-02-03 13:52:11 DEBUG] [__init__:459] Applying before-control 'reliably' on 'method'
[2023-02-03 13:52:11 DEBUG] [python:192] Control module '/opt/hostedtoolcache/Python/3.10.9/x64/lib/python3.10/site-packages/chaosreliably/controls/experiment.py' does not declare 'before_method_control'
[2023-02-03 13:52:11 DEBUG] [__init__:459] Applying before-control 'reliably' on 'activity'
[2023-02-03 13:52:11 DEBUG] [python:192] Control module '/opt/hostedtoolcache/Python/3.10.9/x64/lib/python3.10/site-packages/chaosreliably/controls/experiment.py' does not declare 'before_activity_control'
[2023-02-03 13:52:11 INFO] [activity:215] Probe: list-cloudrun-instances
[2023-02-03 13:52:12 DEBUG] [python:33] Activity 'list-cloudrun-instances' loaded from '/opt/hostedtoolcache/Python/3.10.9/x64/lib/python3.10/site-packages/chaosgcp/cloudrun/probes.py'
[2023-02-03 13:52:12 DEBUG] [activity:292] Activity failed
    Traceback (most recent call last):
      File "/opt/hostedtoolcache/Python/3.10.9/x64/lib/python3.10/site-packages/chaoslib/provider/python.py", line 56, in run_python_activity
        return func(**arguments)
      File "/opt/hostedtoolcache/Python/3.10.9/x64/lib/python3.10/site-packages/chaosgcp/cloudrun/probes.py", line 52, in list_services
        credentials = load_credentials(secrets)
      File "/opt/hostedtoolcache/Python/3.10.9/x64/lib/python3.10/site-packages/chaosgcp/__init__.py", line 190, in load_credentials
        raise FailedActivity(
    chaoslib.exceptions.ActivityFailed: missing GCP credentials settings in secrets of this activity
    
    During handling of the above exception, another exception occurred:
    
    Traceback (most recent call last):
      File "/opt/hostedtoolcache/Python/3.10.9/x64/lib/python3.10/site-packages/chaoslib/activity.py", line 285, in run_activity
        result = run_python_activity(activity, configuration, secrets)
      File "/opt/hostedtoolcache/Python/3.10.9/x64/lib/python3.10/site-packages/chaoslib/provider/python.py", line 58, in run_python_activity
        raise ActivityFailed(
      File "/opt/hostedtoolcache/Python/3.10.9/x64/lib/python3.10/site-packages/chaoslib/provider/python.py", line 56, in run_python_activity
        return func(**arguments)
      File "/opt/hostedtoolcache/Python/3.10.9/x64/lib/python3.10/site-packages/chaosgcp/cloudrun/probes.py", line 52, in list_services
        credentials = load_credentials(secrets)
      File "/opt/hostedtoolcache/Python/3.10.9/x64/lib/python3.10/site-packages/chaosgcp/__init__.py", line 190, in load_credentials
        raise FailedActivity(
    chaoslib.exceptions.ActivityFailed: chaoslib.exceptions.ActivityFailed: missing GCP credentials settings in secrets of this activity
[2023-02-03 13:52:12 ERROR] [activity:243]   => failed: chaoslib.exceptions.ActivityFailed: missing GCP credentials settings in secrets of this activity
[2023-02-03 13:52:12 DEBUG] [__init__:459] Applying after-control 'reliably' on 'activity'
[2023-02-03 13:52:12 DEBUG] [python:192] Control module '/opt/hostedtoolcache/Python/3.10.9/x64/lib/python3.10/site-packages/chaosreliably/controls/experiment.py' does not declare 'after_activity_control'
[2023-02-03 13:52:12 DEBUG] [__init__:459] Applying after-control 'reliably' on 'method'
[2023-02-03 13:52:12 DEBUG] [python:192] Control module '/opt/hostedtoolcache/Python/3.10.9/x64/lib/python3.10/site-packages/chaosreliably/controls/experiment.py' does not declare 'after_method_control'
[2023-02-03 13:52:12 WARNING] [run:707] Rollbacks were explicitly requested to be played
[2023-02-03 13:52:12 INFO] [run:944] Let's rollback...
[2023-02-03 13:52:12 DEBUG] [__init__:459] Applying before-control 'reliably' on 'rollback'
[2023-02-03 13:52:12 DEBUG] [python:192] Control module '/opt/hostedtoolcache/Python/3.10.9/x64/lib/python3.10/site-packages/chaosreliably/controls/experiment.py' does not declare 'before_rollback_control'
[2023-02-03 13:52:12 INFO] [rollback:31] No declared rollbacks, let's move on.
[2023-02-03 13:52:12 DEBUG] [__init__:459] Applying after-control 'reliably' on 'rollback'
[2023-02-03 13:52:12 DEBUG] [python:192] Control module '/opt/hostedtoolcache/Python/3.10.9/x64/lib/python3.10/site-packages/chaosreliably/controls/experiment.py' does not declare 'after_rollback_control'
[2023-02-03 13:52:12 INFO] [run:511] Experiment ended with status: completed
[2023-02-03 13:52:12 DEBUG] [__init__:459] Applying after-control 'reliably' on 'experiment'
[2023-02-03 13:52:12 DEBUG] [python:192] Control module '/opt/hostedtoolcache/Python/3.10.9/x64/lib/python3.10/site-packages/chaosreliably/controls/experiment.py' does not declare 'after_experiment_control'
[2023-02-03 13:52:12 DEBUG] [__init__:103] Cleaning up controls
[2023-02-03 13:52:12 DEBUG] [__init__:112] Cleaning up control 'reliably'
[2023-02-03 13:52:12 DEBUG] [python:192] Control module '/opt/hostedtoolcache/Python/3.10.9/x64/lib/python3.10/site-packages/chaosreliably/controls/experiment.py' does not declare 'cleanup_control'
[2023-02-03 13:52:12 INFO] [experiment:236] Finishing Reliably execution...
[2023-02-03 13:52:12 DEBUG] [experiment:156] Stopping Reliably state checker now
[2023-02-03 13:52:13 INFO] [experiment:289] Finished Reliably execution. Bye!
[2023-02-03 13:52:13 DEBUG] [caching:42] Clearing activities cache
