{
  "chaoslib-version": "1.33.1",
  "platform": "Linux-5.15.0-1031-azure-x86_64-with-glibc2.35",
  "node": "fv-az565-672",
  "experiment": {
    "title": "List cloud run instances",
    "method": [
      {
        "name": "list-cloudrun-instances",
        "type": "probe",
        "provider": {
          "func": "list_services",
          "type": "python",
          "module": "chaosgcp.cloudrun.probes",
          "arguments": {
            "parent": "projects/reliably-staging-project/locations/europe-west1"
          }
        }
      }
    ],
    "version": "1.0.0",
    "controls": [
      {
        "name": "reliably",
        "provider": {
          "type": "python",
          "module": "chaosreliably.controls.experiment",
          "arguments": {
            "exp_id": "4556a14b-e776-4cd1-a6b1-c320e06bde2c",
            "org_id": "8f67bb6a-4944-40af-80b0-921023467cdc"
          }
        }
      }
    ],
    "description": "n/a",
    "contributions": {
      "security": "none",
      "performance": "none",
      "availability": "none"
    },
    "dry": null,
    "extensions": [
      {
        "name": "reliably",
        "pauses": [],
        "termination": null,
        "execution_url": "https://app.reliably.dev/executions/view/?id=3ea37a66-be45-4245-9dc6-26c1bf55a2d2&exp=4556a14b-e776-4cd1-a6b1-c320e06bde2c"
      }
    ]
  },
  "start": "2023-02-03T13:52:10.738803",
  "status": "completed",
  "deviated": false,
  "steady_states": {
    "before": null,
    "after": null,
    "during": []
  },
  "run": [
    {
      "activity": {
        "name": "list-cloudrun-instances",
        "type": "probe",
        "provider": {
          "func": "list_services",
          "type": "python",
          "module": "chaosgcp.cloudrun.probes",
          "arguments": {
            "parent": "projects/reliably-staging-project/locations/europe-west1"
          }
        }
      },
      "output": null,
      "start": "2023-02-03T13:52:11.452535",
      "status": "failed",
      "exception": [
        "Traceback (most recent call last):\n",
        "  File \"/opt/hostedtoolcache/Python/3.10.9/x64/lib/python3.10/site-packages/chaoslib/provider/python.py\", line 56, in run_python_activity\n    return func(**arguments)\n",
        "  File \"/opt/hostedtoolcache/Python/3.10.9/x64/lib/python3.10/site-packages/chaosgcp/cloudrun/probes.py\", line 52, in list_services\n    credentials = load_credentials(secrets)\n",
        "  File \"/opt/hostedtoolcache/Python/3.10.9/x64/lib/python3.10/site-packages/chaosgcp/__init__.py\", line 190, in load_credentials\n    raise FailedActivity(\n",
        "chaoslib.exceptions.ActivityFailed: missing GCP credentials settings in secrets of this activity\n",
        "\nDuring handling of the above exception, another exception occurred:\n\n",
        "chaoslib.exceptions.ActivityFailed: chaoslib.exceptions.ActivityFailed: missing GCP credentials settings in secrets of this activity\n"
      ],
      "end": "2023-02-03T13:52:12.039442",
      "duration": 0.586907
    }
  ],
  "rollbacks": [],
  "end": "2023-02-03T13:52:12.369805",
  "duration": 1.632892370223999
}