[2022-12-09 15:59:54 DEBUG] [cli:112] ###############################################################################
[2022-12-09 15:59:54 DEBUG] [cli:113] Running command 'run'
[2022-12-09 15:59:54 DEBUG] [cli:117] Using settings file '/home/runner/.chaostoolkit/settings.yaml'
[2022-12-09 15:59:54 DEBUG] [settings:30] The Chaos Toolkit settings file could not be found at '/home/runner/.chaostoolkit/settings.yaml'.
[2022-12-09 15:59:54 DEBUG] [__init__:399] No controls to apply on 'loader'
[2022-12-09 15:59:54 DEBUG] [loader:129] Fetched experiment: 
    {"title":"Latency remains under 200ms","method":[],"version":"1.0.0","controls":[{"name":"reliably","provider":{"type":"python","module":"chaosreliably.controls.experiment","arguments":{"exp_id":"af794e96-6099-4b1a-b379-5c8f91d91ba0","org_id":"8f67bb6a-4944-40af-80b0-921023467cdc"}}}],"description":"Verify that our endpoint responds under a reasonable amount of time","configuration":{"reliably_url":"https://reliably.com","reliably_latency":0.2},"steady-state-hypothesis":{"title":"capture-response-time-and-verify-it","probes":[{"name":"measure-endpoint-response-time","type":"probe","provider":{"func":"measure_response_time","type":"python","module":"chaosreliably.activities.http.probes","arguments":{"url":"${reliably_url}"}},"tolerance":{"name":"validate-response-time","type":"probe","provider":{"func":"response_time_must_be_under","type":"python","module":"chaosreliably.activities.http.tolerances","arguments":{"latency":"${reliably_latency}"}}}}]}}
[2022-12-09 15:59:54 DEBUG] [__init__:399] No controls to apply on 'loader'
[2022-12-09 15:59:54 DEBUG] [caching:24] Building activity cache...
[2022-12-09 15:59:54 DEBUG] [caching:35] Cached 1 activities
[2022-12-09 15:59:54 INFO] [experiment:58] Validating the experiment's syntax
[2022-12-09 15:59:54 DEBUG] [configuration:63] Loading configuration...
[2022-12-09 15:59:54 DEBUG] [secret:78] Loading secrets...
[2022-12-09 15:59:54 DEBUG] [secret:104] Done loading secrets
[2022-12-09 15:59:54 DEBUG] [python:192] Control module '/opt/hostedtoolcache/Python/3.10.8/x64/lib/python3.10/site-packages/chaosreliably/controls/experiment.py' does not declare 'validate_control'
[2022-12-09 15:59:54 INFO] [experiment:109] Experiment looks valid
[2022-12-09 15:59:54 DEBUG] [caching:42] Clearing activities cache
[2022-12-09 15:59:54 DEBUG] [caching:24] Building activity cache...
[2022-12-09 15:59:54 DEBUG] [caching:35] Cached 1 activities
[2022-12-09 15:59:54 DEBUG] [configuration:63] Loading configuration...
[2022-12-09 15:59:54 DEBUG] [secret:78] Loading secrets...
[2022-12-09 15:59:54 DEBUG] [secret:104] Done loading secrets
[2022-12-09 15:59:54 DEBUG] [configuration:160] Loading dynamic configuration...
[2022-12-09 15:59:54 INFO] [run:320] Running experiment: Latency remains under 200ms
[2022-12-09 15:59:54 DEBUG] [__init__:52] Initializing controls
[2022-12-09 15:59:54 DEBUG] [__init__:61] Initializing control 'reliably'
[2022-12-09 15:59:54 DEBUG] [python:192] Control module '/opt/hostedtoolcache/Python/3.10.8/x64/lib/python3.10/site-packages/chaosreliably/controls/experiment.py' does not declare 'configure_control'
[2022-12-09 15:59:54 INFO] [run:344] Steady-state strategy: default
[2022-12-09 15:59:54 INFO] [run:348] Rollbacks strategy: always
[2022-12-09 15:59:54 DEBUG] [__init__:409] Applying before-control 'reliably' on 'experiment'
[2022-12-09 15:59:54 DEBUG] [python:196] Control 'before_experiment_control' loaded from '/opt/hostedtoolcache/Python/3.10.8/x64/lib/python3.10/site-packages/chaosreliably/controls/experiment.py'
[2022-12-09 15:59:54 DEBUG] [run:506] Running steady-state hypothesis before the method
[2022-12-09 15:59:54 INFO] [hypothesis:182] Steady state hypothesis: capture-response-time-and-verify-it
[2022-12-09 15:59:54 DEBUG] [__init__:409] Applying before-control 'reliably' on 'hypothesis'
[2022-12-09 15:59:54 DEBUG] [python:192] Control module '/opt/hostedtoolcache/Python/3.10.8/x64/lib/python3.10/site-packages/chaosreliably/controls/experiment.py' does not declare 'before_hypothesis_control'
[2022-12-09 15:59:54 DEBUG] [__init__:409] Applying before-control 'reliably' on 'activity'
[2022-12-09 15:59:54 DEBUG] [python:192] Control module '/opt/hostedtoolcache/Python/3.10.8/x64/lib/python3.10/site-packages/chaosreliably/controls/experiment.py' does not declare 'before_activity_control'
[2022-12-09 15:59:54 INFO] [activity:204] Probe: measure-endpoint-response-time
[2022-12-09 15:59:54 DEBUG] [python:33] Activity 'measure-endpoint-response-time' loaded from '/opt/hostedtoolcache/Python/3.10.8/x64/lib/python3.10/site-packages/chaosreliably/activities/http/probes.py'
[2022-12-09 15:59:55 DEBUG] [activity:221]   => succeeded with '0.124571'
[2022-12-09 15:59:55 DEBUG] [__init__:409] Applying after-control 'reliably' on 'activity'
[2022-12-09 15:59:55 DEBUG] [python:192] Control module '/opt/hostedtoolcache/Python/3.10.8/x64/lib/python3.10/site-packages/chaosreliably/controls/experiment.py' does not declare 'after_activity_control'
[2022-12-09 15:59:55 DEBUG] [hypothesis:221] allowed tolerance is {'name': 'validate-response-time', 'type': 'probe', 'provider': {'func': 'response_time_must_be_under', 'type': 'python', 'module': 'chaosreliably.activities.http.tolerances', 'arguments': {'latency': '${reliably_latency}'}}}
[2022-12-09 15:59:55 DEBUG] [python:33] Activity 'validate-response-time' loaded from '/opt/hostedtoolcache/Python/3.10.8/x64/lib/python3.10/site-packages/chaosreliably/activities/http/tolerances.py'
[2022-12-09 15:59:55 DEBUG] [tolerances:13] Verify that response time is under: 0.2
[2022-12-09 15:59:55 INFO] [hypothesis:231] Steady state hypothesis is met!
[2022-12-09 15:59:55 DEBUG] [__init__:409] Applying after-control 'reliably' on 'hypothesis'
[2022-12-09 15:59:55 DEBUG] [python:192] Control module '/opt/hostedtoolcache/Python/3.10.8/x64/lib/python3.10/site-packages/chaosreliably/controls/experiment.py' does not declare 'after_hypothesis_control'
[2022-12-09 15:59:55 INFO] [run:607] Playing your experiment's method now...
[2022-12-09 15:59:55 DEBUG] [__init__:409] Applying before-control 'reliably' on 'method'
[2022-12-09 15:59:55 DEBUG] [python:192] Control module '/opt/hostedtoolcache/Python/3.10.8/x64/lib/python3.10/site-packages/chaosreliably/controls/experiment.py' does not declare 'before_method_control'
[2022-12-09 15:59:55 INFO] [activity:128] No declared activities, let's move on.
[2022-12-09 15:59:55 DEBUG] [__init__:409] Applying after-control 'reliably' on 'method'
[2022-12-09 15:59:55 DEBUG] [python:192] Control module '/opt/hostedtoolcache/Python/3.10.8/x64/lib/python3.10/site-packages/chaosreliably/controls/experiment.py' does not declare 'after_method_control'
[2022-12-09 15:59:55 DEBUG] [run:536] Running steady-state hypothesis after the method
[2022-12-09 15:59:55 INFO] [hypothesis:182] Steady state hypothesis: capture-response-time-and-verify-it
[2022-12-09 15:59:55 DEBUG] [__init__:409] Applying before-control 'reliably' on 'hypothesis'
[2022-12-09 15:59:55 DEBUG] [python:192] Control module '/opt/hostedtoolcache/Python/3.10.8/x64/lib/python3.10/site-packages/chaosreliably/controls/experiment.py' does not declare 'before_hypothesis_control'
[2022-12-09 15:59:55 DEBUG] [__init__:409] Applying before-control 'reliably' on 'activity'
[2022-12-09 15:59:55 DEBUG] [python:192] Control module '/opt/hostedtoolcache/Python/3.10.8/x64/lib/python3.10/site-packages/chaosreliably/controls/experiment.py' does not declare 'before_activity_control'
[2022-12-09 15:59:55 INFO] [activity:204] Probe: measure-endpoint-response-time
[2022-12-09 15:59:55 DEBUG] [python:33] Activity 'measure-endpoint-response-time' loaded from '/opt/hostedtoolcache/Python/3.10.8/x64/lib/python3.10/site-packages/chaosreliably/activities/http/probes.py'
[2022-12-09 15:59:55 DEBUG] [activity:221]   => succeeded with '0.070902'
[2022-12-09 15:59:55 DEBUG] [__init__:409] Applying after-control 'reliably' on 'activity'
[2022-12-09 15:59:55 DEBUG] [python:192] Control module '/opt/hostedtoolcache/Python/3.10.8/x64/lib/python3.10/site-packages/chaosreliably/controls/experiment.py' does not declare 'after_activity_control'
[2022-12-09 15:59:55 DEBUG] [hypothesis:221] allowed tolerance is {'name': 'validate-response-time', 'type': 'probe', 'provider': {'func': 'response_time_must_be_under', 'type': 'python', 'module': 'chaosreliably.activities.http.tolerances', 'arguments': {'latency': '${reliably_latency}', 'value': 0.124571}}}
[2022-12-09 15:59:55 DEBUG] [python:33] Activity 'validate-response-time' loaded from '/opt/hostedtoolcache/Python/3.10.8/x64/lib/python3.10/site-packages/chaosreliably/activities/http/tolerances.py'
[2022-12-09 15:59:55 DEBUG] [tolerances:13] Verify that response time is under: 0.2
[2022-12-09 15:59:55 INFO] [hypothesis:231] Steady state hypothesis is met!
[2022-12-09 15:59:55 DEBUG] [__init__:409] Applying after-control 'reliably' on 'hypothesis'
[2022-12-09 15:59:55 DEBUG] [python:192] Control module '/opt/hostedtoolcache/Python/3.10.8/x64/lib/python3.10/site-packages/chaosreliably/controls/experiment.py' does not declare 'after_hypothesis_control'
[2022-12-09 15:59:55 WARNING] [run:641] Rollbacks were explicitly requested to be played
[2022-12-09 15:59:55 INFO] [run:893] Let's rollback...
[2022-12-09 15:59:55 DEBUG] [__init__:409] Applying before-control 'reliably' on 'rollback'
[2022-12-09 15:59:55 DEBUG] [python:192] Control module '/opt/hostedtoolcache/Python/3.10.8/x64/lib/python3.10/site-packages/chaosreliably/controls/experiment.py' does not declare 'before_rollback_control'
[2022-12-09 15:59:55 INFO] [rollback:27] No declared rollbacks, let's move on.
[2022-12-09 15:59:55 DEBUG] [__init__:409] Applying after-control 'reliably' on 'rollback'
[2022-12-09 15:59:55 DEBUG] [python:192] Control module '/opt/hostedtoolcache/Python/3.10.8/x64/lib/python3.10/site-packages/chaosreliably/controls/experiment.py' does not declare 'after_rollback_control'
[2022-12-09 15:59:55 INFO] [run:458] Experiment ended with status: completed
[2022-12-09 15:59:55 DEBUG] [__init__:409] Applying after-control 'reliably' on 'experiment'
[2022-12-09 15:59:55 DEBUG] [python:196] Control 'after_experiment_control' loaded from '/opt/hostedtoolcache/Python/3.10.8/x64/lib/python3.10/site-packages/chaosreliably/controls/experiment.py'
[2022-12-09 15:59:55 DEBUG] [__init__:40] Reliably client TLS verification: True
[2022-12-09 15:59:55 DEBUG] [__init__:41] Reliably client scheme: https
[2022-12-09 15:59:55 DEBUG] [experiment:92] Response from https://app.reliably.dev/api/v1/organization/8f67bb6a-4944-40af-80b0-921023467cdc/experiments/af794e96-6099-4b1a-b379-5c8f91d91ba0/executions: 201
[2022-12-09 15:59:55 DEBUG] [__init__:91] Cleaning up controls
[2022-12-09 15:59:55 DEBUG] [__init__:100] Cleaning up control 'reliably'
[2022-12-09 15:59:55 DEBUG] [python:192] Control module '/opt/hostedtoolcache/Python/3.10.8/x64/lib/python3.10/site-packages/chaosreliably/controls/experiment.py' does not declare 'cleanup_control'
[2022-12-09 15:59:55 DEBUG] [caching:42] Clearing activities cache
[2022-12-09 16:31:42 DEBUG] [cli:112] ###############################################################################
[2022-12-09 16:31:42 DEBUG] [cli:113] Running command 'run'
[2022-12-09 16:31:42 DEBUG] [cli:117] Using settings file '/home/runner/.chaostoolkit/settings.yaml'
[2022-12-09 16:31:42 DEBUG] [settings:30] The Chaos Toolkit settings file could not be found at '/home/runner/.chaostoolkit/settings.yaml'.
[2022-12-09 16:31:42 DEBUG] [__init__:399] No controls to apply on 'loader'
[2022-12-09 16:31:42 DEBUG] [loader:129] Fetched experiment: 
    {"title":"Latency remains under 200ms","method":[],"version":"1.0.0","controls":[{"name":"reliably","provider":{"type":"python","module":"chaosreliably.controls.experiment","arguments":{"exp_id":"af794e96-6099-4b1a-b379-5c8f91d91ba0","org_id":"8f67bb6a-4944-40af-80b0-921023467cdc"}}}],"description":"Verify that our endpoint responds under a reasonable amount of time","configuration":{"reliably_url":"https://reliably.com","reliably_latency":0.2},"steady-state-hypothesis":{"title":"capture-response-time-and-verify-it","probes":[{"name":"measure-endpoint-response-time","type":"probe","provider":{"func":"measure_response_time","type":"python","module":"chaosreliably.activities.http.probes","arguments":{"url":"${reliably_url}"}},"tolerance":{"name":"validate-response-time","type":"probe","provider":{"func":"response_time_must_be_under","type":"python","module":"chaosreliably.activities.http.tolerances","arguments":{"latency":"${reliably_latency}"}}}}]}}
[2022-12-09 16:31:42 DEBUG] [__init__:399] No controls to apply on 'loader'
[2022-12-09 16:31:42 DEBUG] [caching:24] Building activity cache...
[2022-12-09 16:31:42 DEBUG] [caching:35] Cached 1 activities
[2022-12-09 16:31:42 INFO] [experiment:58] Validating the experiment's syntax
[2022-12-09 16:31:42 DEBUG] [configuration:63] Loading configuration...
[2022-12-09 16:31:42 DEBUG] [secret:78] Loading secrets...
[2022-12-09 16:31:42 DEBUG] [secret:104] Done loading secrets
[2022-12-09 16:31:42 DEBUG] [python:192] Control module '/opt/hostedtoolcache/Python/3.10.8/x64/lib/python3.10/site-packages/chaosreliably/controls/experiment.py' does not declare 'validate_control'
[2022-12-09 16:31:42 INFO] [experiment:109] Experiment looks valid
[2022-12-09 16:31:42 DEBUG] [caching:42] Clearing activities cache
[2022-12-09 16:31:42 DEBUG] [caching:24] Building activity cache...
[2022-12-09 16:31:42 DEBUG] [caching:35] Cached 1 activities
[2022-12-09 16:31:42 DEBUG] [configuration:63] Loading configuration...
[2022-12-09 16:31:42 DEBUG] [secret:78] Loading secrets...
[2022-12-09 16:31:42 DEBUG] [secret:104] Done loading secrets
[2022-12-09 16:31:42 DEBUG] [configuration:160] Loading dynamic configuration...
[2022-12-09 16:31:42 INFO] [run:320] Running experiment: Latency remains under 200ms
[2022-12-09 16:31:42 DEBUG] [__init__:52] Initializing controls
[2022-12-09 16:31:42 DEBUG] [__init__:61] Initializing control 'reliably'
[2022-12-09 16:31:42 DEBUG] [python:192] Control module '/opt/hostedtoolcache/Python/3.10.8/x64/lib/python3.10/site-packages/chaosreliably/controls/experiment.py' does not declare 'configure_control'
[2022-12-09 16:31:42 INFO] [run:344] Steady-state strategy: default
[2022-12-09 16:31:42 INFO] [run:348] Rollbacks strategy: always
[2022-12-09 16:31:42 DEBUG] [__init__:409] Applying before-control 'reliably' on 'experiment'
[2022-12-09 16:31:42 DEBUG] [python:196] Control 'before_experiment_control' loaded from '/opt/hostedtoolcache/Python/3.10.8/x64/lib/python3.10/site-packages/chaosreliably/controls/experiment.py'
[2022-12-09 16:31:42 DEBUG] [run:506] Running steady-state hypothesis before the method
[2022-12-09 16:31:42 INFO] [hypothesis:182] Steady state hypothesis: capture-response-time-and-verify-it
[2022-12-09 16:31:42 DEBUG] [__init__:409] Applying before-control 'reliably' on 'hypothesis'
[2022-12-09 16:31:42 DEBUG] [python:192] Control module '/opt/hostedtoolcache/Python/3.10.8/x64/lib/python3.10/site-packages/chaosreliably/controls/experiment.py' does not declare 'before_hypothesis_control'
[2022-12-09 16:31:42 DEBUG] [__init__:409] Applying before-control 'reliably' on 'activity'
[2022-12-09 16:31:42 DEBUG] [python:192] Control module '/opt/hostedtoolcache/Python/3.10.8/x64/lib/python3.10/site-packages/chaosreliably/controls/experiment.py' does not declare 'before_activity_control'
[2022-12-09 16:31:42 INFO] [activity:204] Probe: measure-endpoint-response-time
[2022-12-09 16:31:42 DEBUG] [python:33] Activity 'measure-endpoint-response-time' loaded from '/opt/hostedtoolcache/Python/3.10.8/x64/lib/python3.10/site-packages/chaosreliably/activities/http/probes.py'
[2022-12-09 16:31:42 DEBUG] [activity:221]   => succeeded with '0.149519'
[2022-12-09 16:31:42 DEBUG] [__init__:409] Applying after-control 'reliably' on 'activity'
[2022-12-09 16:31:42 DEBUG] [python:192] Control module '/opt/hostedtoolcache/Python/3.10.8/x64/lib/python3.10/site-packages/chaosreliably/controls/experiment.py' does not declare 'after_activity_control'
[2022-12-09 16:31:42 DEBUG] [hypothesis:221] allowed tolerance is {'name': 'validate-response-time', 'type': 'probe', 'provider': {'func': 'response_time_must_be_under', 'type': 'python', 'module': 'chaosreliably.activities.http.tolerances', 'arguments': {'latency': '${reliably_latency}'}}}
[2022-12-09 16:31:42 DEBUG] [python:33] Activity 'validate-response-time' loaded from '/opt/hostedtoolcache/Python/3.10.8/x64/lib/python3.10/site-packages/chaosreliably/activities/http/tolerances.py'
[2022-12-09 16:31:42 DEBUG] [tolerances:13] Verify that response time is under: 0.2
[2022-12-09 16:31:42 INFO] [hypothesis:231] Steady state hypothesis is met!
[2022-12-09 16:31:42 DEBUG] [__init__:409] Applying after-control 'reliably' on 'hypothesis'
[2022-12-09 16:31:42 DEBUG] [python:192] Control module '/opt/hostedtoolcache/Python/3.10.8/x64/lib/python3.10/site-packages/chaosreliably/controls/experiment.py' does not declare 'after_hypothesis_control'
[2022-12-09 16:31:42 INFO] [run:607] Playing your experiment's method now...
[2022-12-09 16:31:42 DEBUG] [__init__:409] Applying before-control 'reliably' on 'method'
[2022-12-09 16:31:42 DEBUG] [python:192] Control module '/opt/hostedtoolcache/Python/3.10.8/x64/lib/python3.10/site-packages/chaosreliably/controls/experiment.py' does not declare 'before_method_control'
[2022-12-09 16:31:42 INFO] [activity:128] No declared activities, let's move on.
[2022-12-09 16:31:42 DEBUG] [__init__:409] Applying after-control 'reliably' on 'method'
[2022-12-09 16:31:42 DEBUG] [python:192] Control module '/opt/hostedtoolcache/Python/3.10.8/x64/lib/python3.10/site-packages/chaosreliably/controls/experiment.py' does not declare 'after_method_control'
[2022-12-09 16:31:42 DEBUG] [run:536] Running steady-state hypothesis after the method
[2022-12-09 16:31:42 INFO] [hypothesis:182] Steady state hypothesis: capture-response-time-and-verify-it
[2022-12-09 16:31:42 DEBUG] [__init__:409] Applying before-control 'reliably' on 'hypothesis'
[2022-12-09 16:31:42 DEBUG] [python:192] Control module '/opt/hostedtoolcache/Python/3.10.8/x64/lib/python3.10/site-packages/chaosreliably/controls/experiment.py' does not declare 'before_hypothesis_control'
[2022-12-09 16:31:42 DEBUG] [__init__:409] Applying before-control 'reliably' on 'activity'
[2022-12-09 16:31:42 DEBUG] [python:192] Control module '/opt/hostedtoolcache/Python/3.10.8/x64/lib/python3.10/site-packages/chaosreliably/controls/experiment.py' does not declare 'before_activity_control'
[2022-12-09 16:31:42 INFO] [activity:204] Probe: measure-endpoint-response-time
[2022-12-09 16:31:42 DEBUG] [python:33] Activity 'measure-endpoint-response-time' loaded from '/opt/hostedtoolcache/Python/3.10.8/x64/lib/python3.10/site-packages/chaosreliably/activities/http/probes.py'
[2022-12-09 16:31:43 DEBUG] [activity:221]   => succeeded with '0.178813'
[2022-12-09 16:31:43 DEBUG] [__init__:409] Applying after-control 'reliably' on 'activity'
[2022-12-09 16:31:43 DEBUG] [python:192] Control module '/opt/hostedtoolcache/Python/3.10.8/x64/lib/python3.10/site-packages/chaosreliably/controls/experiment.py' does not declare 'after_activity_control'
[2022-12-09 16:31:43 DEBUG] [hypothesis:221] allowed tolerance is {'name': 'validate-response-time', 'type': 'probe', 'provider': {'func': 'response_time_must_be_under', 'type': 'python', 'module': 'chaosreliably.activities.http.tolerances', 'arguments': {'latency': '${reliably_latency}', 'value': 0.149519}}}
[2022-12-09 16:31:43 DEBUG] [python:33] Activity 'validate-response-time' loaded from '/opt/hostedtoolcache/Python/3.10.8/x64/lib/python3.10/site-packages/chaosreliably/activities/http/tolerances.py'
[2022-12-09 16:31:43 DEBUG] [tolerances:13] Verify that response time is under: 0.2
[2022-12-09 16:31:43 INFO] [hypothesis:231] Steady state hypothesis is met!
[2022-12-09 16:31:43 DEBUG] [__init__:409] Applying after-control 'reliably' on 'hypothesis'
[2022-12-09 16:31:43 DEBUG] [python:192] Control module '/opt/hostedtoolcache/Python/3.10.8/x64/lib/python3.10/site-packages/chaosreliably/controls/experiment.py' does not declare 'after_hypothesis_control'
[2022-12-09 16:31:43 WARNING] [run:641] Rollbacks were explicitly requested to be played
[2022-12-09 16:31:43 INFO] [run:893] Let's rollback...
[2022-12-09 16:31:43 DEBUG] [__init__:409] Applying before-control 'reliably' on 'rollback'
[2022-12-09 16:31:43 DEBUG] [python:192] Control module '/opt/hostedtoolcache/Python/3.10.8/x64/lib/python3.10/site-packages/chaosreliably/controls/experiment.py' does not declare 'before_rollback_control'
[2022-12-09 16:31:43 INFO] [rollback:27] No declared rollbacks, let's move on.
[2022-12-09 16:31:43 DEBUG] [__init__:409] Applying after-control 'reliably' on 'rollback'
[2022-12-09 16:31:43 DEBUG] [python:192] Control module '/opt/hostedtoolcache/Python/3.10.8/x64/lib/python3.10/site-packages/chaosreliably/controls/experiment.py' does not declare 'after_rollback_control'
[2022-12-09 16:31:43 INFO] [run:458] Experiment ended with status: completed
[2022-12-09 16:31:43 DEBUG] [__init__:409] Applying after-control 'reliably' on 'experiment'
[2022-12-09 16:31:43 DEBUG] [python:196] Control 'after_experiment_control' loaded from '/opt/hostedtoolcache/Python/3.10.8/x64/lib/python3.10/site-packages/chaosreliably/controls/experiment.py'
[2022-12-09 16:31:43 DEBUG] [__init__:40] Reliably client TLS verification: True
[2022-12-09 16:31:43 DEBUG] [__init__:41] Reliably client scheme: https
[2022-12-09 16:31:43 DEBUG] [experiment:92] Response from https://app.reliably.dev/api/v1/organization/8f67bb6a-4944-40af-80b0-921023467cdc/experiments/af794e96-6099-4b1a-b379-5c8f91d91ba0/executions: 201
[2022-12-09 16:31:43 DEBUG] [__init__:91] Cleaning up controls
[2022-12-09 16:31:43 DEBUG] [__init__:100] Cleaning up control 'reliably'
[2022-12-09 16:31:43 DEBUG] [python:192] Control module '/opt/hostedtoolcache/Python/3.10.8/x64/lib/python3.10/site-packages/chaosreliably/controls/experiment.py' does not declare 'cleanup_control'
[2022-12-09 16:31:43 DEBUG] [caching:42] Clearing activities cache
[2022-12-09 17:08:46 DEBUG] [cli:112] ###############################################################################
[2022-12-09 17:08:46 DEBUG] [cli:113] Running command 'run'
[2022-12-09 17:08:46 DEBUG] [cli:117] Using settings file '/home/runner/.chaostoolkit/settings.yaml'
[2022-12-09 17:08:46 DEBUG] [settings:30] The Chaos Toolkit settings file could not be found at '/home/runner/.chaostoolkit/settings.yaml'.
[2022-12-09 17:08:46 DEBUG] [__init__:399] No controls to apply on 'loader'
[2022-12-09 17:08:46 DEBUG] [loader:129] Fetched experiment: 
    {"title":"Latency remains under 200ms","method":[],"version":"1.0.0","controls":[{"name":"reliably","provider":{"type":"python","module":"chaosreliably.controls.experiment","arguments":{"exp_id":"af794e96-6099-4b1a-b379-5c8f91d91ba0","org_id":"8f67bb6a-4944-40af-80b0-921023467cdc"}}}],"description":"Verify that our endpoint responds under a reasonable amount of time","configuration":{"reliably_url":"https://reliably.com","reliably_latency":0.2},"steady-state-hypothesis":{"title":"capture-response-time-and-verify-it","probes":[{"name":"measure-endpoint-response-time","type":"probe","provider":{"func":"measure_response_time","type":"python","module":"chaosreliably.activities.http.probes","arguments":{"url":"${reliably_url}"}},"tolerance":{"name":"validate-response-time","type":"probe","provider":{"func":"response_time_must_be_under","type":"python","module":"chaosreliably.activities.http.tolerances","arguments":{"latency":"${reliably_latency}"}}}}]}}
[2022-12-09 17:08:46 DEBUG] [__init__:399] No controls to apply on 'loader'
[2022-12-09 17:08:46 DEBUG] [caching:24] Building activity cache...
[2022-12-09 17:08:46 DEBUG] [caching:35] Cached 1 activities
[2022-12-09 17:08:46 INFO] [experiment:58] Validating the experiment's syntax
[2022-12-09 17:08:46 DEBUG] [configuration:63] Loading configuration...
[2022-12-09 17:08:46 DEBUG] [secret:78] Loading secrets...
[2022-12-09 17:08:46 DEBUG] [secret:104] Done loading secrets
[2022-12-09 17:08:46 DEBUG] [python:192] Control module '/opt/hostedtoolcache/Python/3.10.8/x64/lib/python3.10/site-packages/chaosreliably/controls/experiment.py' does not declare 'validate_control'
[2022-12-09 17:08:46 INFO] [experiment:109] Experiment looks valid
[2022-12-09 17:08:46 DEBUG] [caching:42] Clearing activities cache
[2022-12-09 17:08:46 DEBUG] [caching:24] Building activity cache...
[2022-12-09 17:08:46 DEBUG] [caching:35] Cached 1 activities
[2022-12-09 17:08:46 DEBUG] [configuration:63] Loading configuration...
[2022-12-09 17:08:46 DEBUG] [secret:78] Loading secrets...
[2022-12-09 17:08:46 DEBUG] [secret:104] Done loading secrets
[2022-12-09 17:08:46 DEBUG] [configuration:160] Loading dynamic configuration...
[2022-12-09 17:08:46 INFO] [run:320] Running experiment: Latency remains under 200ms
[2022-12-09 17:08:46 DEBUG] [__init__:52] Initializing controls
[2022-12-09 17:08:46 DEBUG] [__init__:61] Initializing control 'reliably'
[2022-12-09 17:08:46 DEBUG] [python:192] Control module '/opt/hostedtoolcache/Python/3.10.8/x64/lib/python3.10/site-packages/chaosreliably/controls/experiment.py' does not declare 'configure_control'
[2022-12-09 17:08:46 INFO] [run:344] Steady-state strategy: default
[2022-12-09 17:08:46 INFO] [run:348] Rollbacks strategy: always
[2022-12-09 17:08:46 DEBUG] [__init__:409] Applying before-control 'reliably' on 'experiment'
[2022-12-09 17:08:46 DEBUG] [python:196] Control 'before_experiment_control' loaded from '/opt/hostedtoolcache/Python/3.10.8/x64/lib/python3.10/site-packages/chaosreliably/controls/experiment.py'
[2022-12-09 17:08:46 DEBUG] [run:506] Running steady-state hypothesis before the method
[2022-12-09 17:08:46 INFO] [hypothesis:182] Steady state hypothesis: capture-response-time-and-verify-it
[2022-12-09 17:08:46 DEBUG] [__init__:409] Applying before-control 'reliably' on 'hypothesis'
[2022-12-09 17:08:46 DEBUG] [python:192] Control module '/opt/hostedtoolcache/Python/3.10.8/x64/lib/python3.10/site-packages/chaosreliably/controls/experiment.py' does not declare 'before_hypothesis_control'
[2022-12-09 17:08:46 DEBUG] [__init__:409] Applying before-control 'reliably' on 'activity'
[2022-12-09 17:08:46 DEBUG] [python:192] Control module '/opt/hostedtoolcache/Python/3.10.8/x64/lib/python3.10/site-packages/chaosreliably/controls/experiment.py' does not declare 'before_activity_control'
[2022-12-09 17:08:46 INFO] [activity:204] Probe: measure-endpoint-response-time
[2022-12-09 17:08:46 DEBUG] [python:33] Activity 'measure-endpoint-response-time' loaded from '/opt/hostedtoolcache/Python/3.10.8/x64/lib/python3.10/site-packages/chaosreliably/activities/http/probes.py'
[2022-12-09 17:08:47 DEBUG] [activity:221]   => succeeded with '0.179233'
[2022-12-09 17:08:47 DEBUG] [__init__:409] Applying after-control 'reliably' on 'activity'
[2022-12-09 17:08:47 DEBUG] [python:192] Control module '/opt/hostedtoolcache/Python/3.10.8/x64/lib/python3.10/site-packages/chaosreliably/controls/experiment.py' does not declare 'after_activity_control'
[2022-12-09 17:08:47 DEBUG] [hypothesis:221] allowed tolerance is {'name': 'validate-response-time', 'type': 'probe', 'provider': {'func': 'response_time_must_be_under', 'type': 'python', 'module': 'chaosreliably.activities.http.tolerances', 'arguments': {'latency': '${reliably_latency}'}}}
[2022-12-09 17:08:47 DEBUG] [python:33] Activity 'validate-response-time' loaded from '/opt/hostedtoolcache/Python/3.10.8/x64/lib/python3.10/site-packages/chaosreliably/activities/http/tolerances.py'
[2022-12-09 17:08:47 DEBUG] [tolerances:13] Verify that response time is under: 0.2
[2022-12-09 17:08:47 INFO] [hypothesis:231] Steady state hypothesis is met!
[2022-12-09 17:08:47 DEBUG] [__init__:409] Applying after-control 'reliably' on 'hypothesis'
[2022-12-09 17:08:47 DEBUG] [python:192] Control module '/opt/hostedtoolcache/Python/3.10.8/x64/lib/python3.10/site-packages/chaosreliably/controls/experiment.py' does not declare 'after_hypothesis_control'
[2022-12-09 17:08:47 INFO] [run:607] Playing your experiment's method now...
[2022-12-09 17:08:47 DEBUG] [__init__:409] Applying before-control 'reliably' on 'method'
[2022-12-09 17:08:47 DEBUG] [python:192] Control module '/opt/hostedtoolcache/Python/3.10.8/x64/lib/python3.10/site-packages/chaosreliably/controls/experiment.py' does not declare 'before_method_control'
[2022-12-09 17:08:47 INFO] [activity:128] No declared activities, let's move on.
[2022-12-09 17:08:47 DEBUG] [__init__:409] Applying after-control 'reliably' on 'method'
[2022-12-09 17:08:47 DEBUG] [python:192] Control module '/opt/hostedtoolcache/Python/3.10.8/x64/lib/python3.10/site-packages/chaosreliably/controls/experiment.py' does not declare 'after_method_control'
[2022-12-09 17:08:47 DEBUG] [run:536] Running steady-state hypothesis after the method
[2022-12-09 17:08:47 INFO] [hypothesis:182] Steady state hypothesis: capture-response-time-and-verify-it
[2022-12-09 17:08:47 DEBUG] [__init__:409] Applying before-control 'reliably' on 'hypothesis'
[2022-12-09 17:08:47 DEBUG] [python:192] Control module '/opt/hostedtoolcache/Python/3.10.8/x64/lib/python3.10/site-packages/chaosreliably/controls/experiment.py' does not declare 'before_hypothesis_control'
[2022-12-09 17:08:47 DEBUG] [__init__:409] Applying before-control 'reliably' on 'activity'
[2022-12-09 17:08:47 DEBUG] [python:192] Control module '/opt/hostedtoolcache/Python/3.10.8/x64/lib/python3.10/site-packages/chaosreliably/controls/experiment.py' does not declare 'before_activity_control'
[2022-12-09 17:08:47 INFO] [activity:204] Probe: measure-endpoint-response-time
[2022-12-09 17:08:47 DEBUG] [python:33] Activity 'measure-endpoint-response-time' loaded from '/opt/hostedtoolcache/Python/3.10.8/x64/lib/python3.10/site-packages/chaosreliably/activities/http/probes.py'
[2022-12-09 17:08:47 DEBUG] [activity:221]   => succeeded with '0.149322'
[2022-12-09 17:08:47 DEBUG] [__init__:409] Applying after-control 'reliably' on 'activity'
[2022-12-09 17:08:47 DEBUG] [python:192] Control module '/opt/hostedtoolcache/Python/3.10.8/x64/lib/python3.10/site-packages/chaosreliably/controls/experiment.py' does not declare 'after_activity_control'
[2022-12-09 17:08:47 DEBUG] [hypothesis:221] allowed tolerance is {'name': 'validate-response-time', 'type': 'probe', 'provider': {'func': 'response_time_must_be_under', 'type': 'python', 'module': 'chaosreliably.activities.http.tolerances', 'arguments': {'latency': '${reliably_latency}', 'value': 0.179233}}}
[2022-12-09 17:08:47 DEBUG] [python:33] Activity 'validate-response-time' loaded from '/opt/hostedtoolcache/Python/3.10.8/x64/lib/python3.10/site-packages/chaosreliably/activities/http/tolerances.py'
[2022-12-09 17:08:47 DEBUG] [tolerances:13] Verify that response time is under: 0.2
[2022-12-09 17:08:47 INFO] [hypothesis:231] Steady state hypothesis is met!
[2022-12-09 17:08:47 DEBUG] [__init__:409] Applying after-control 'reliably' on 'hypothesis'
[2022-12-09 17:08:47 DEBUG] [python:192] Control module '/opt/hostedtoolcache/Python/3.10.8/x64/lib/python3.10/site-packages/chaosreliably/controls/experiment.py' does not declare 'after_hypothesis_control'
[2022-12-09 17:08:47 WARNING] [run:641] Rollbacks were explicitly requested to be played
[2022-12-09 17:08:47 INFO] [run:893] Let's rollback...
[2022-12-09 17:08:47 DEBUG] [__init__:409] Applying before-control 'reliably' on 'rollback'
[2022-12-09 17:08:47 DEBUG] [python:192] Control module '/opt/hostedtoolcache/Python/3.10.8/x64/lib/python3.10/site-packages/chaosreliably/controls/experiment.py' does not declare 'before_rollback_control'
[2022-12-09 17:08:47 INFO] [rollback:27] No declared rollbacks, let's move on.
[2022-12-09 17:08:47 DEBUG] [__init__:409] Applying after-control 'reliably' on 'rollback'
[2022-12-09 17:08:47 DEBUG] [python:192] Control module '/opt/hostedtoolcache/Python/3.10.8/x64/lib/python3.10/site-packages/chaosreliably/controls/experiment.py' does not declare 'after_rollback_control'
[2022-12-09 17:08:47 INFO] [run:458] Experiment ended with status: completed
[2022-12-09 17:08:47 DEBUG] [__init__:409] Applying after-control 'reliably' on 'experiment'
[2022-12-09 17:08:47 DEBUG] [python:196] Control 'after_experiment_control' loaded from '/opt/hostedtoolcache/Python/3.10.8/x64/lib/python3.10/site-packages/chaosreliably/controls/experiment.py'
[2022-12-09 17:08:47 DEBUG] [__init__:40] Reliably client TLS verification: True
[2022-12-09 17:08:47 DEBUG] [__init__:41] Reliably client scheme: https
[2022-12-09 17:08:47 DEBUG] [experiment:92] Response from https://app.reliably.dev/api/v1/organization/8f67bb6a-4944-40af-80b0-921023467cdc/experiments/af794e96-6099-4b1a-b379-5c8f91d91ba0/executions: 201
[2022-12-09 17:08:47 DEBUG] [__init__:91] Cleaning up controls
[2022-12-09 17:08:47 DEBUG] [__init__:100] Cleaning up control 'reliably'
[2022-12-09 17:08:47 DEBUG] [python:192] Control module '/opt/hostedtoolcache/Python/3.10.8/x64/lib/python3.10/site-packages/chaosreliably/controls/experiment.py' does not declare 'cleanup_control'
[2022-12-09 17:08:47 DEBUG] [caching:42] Clearing activities cache
