{
  "chaoslib-version": "1.33.1",
  "platform": "Linux-5.15.0-1031-azure-x86_64-with-glibc2.35",
  "node": "fv-az583-70",
  "experiment": {
    "title": "List cloud run instances",
    "method": [
      {
        "name": "list-cloudrun-instances",
        "type": "probe",
        "provider": {
          "func": "list_services",
          "type": "python",
          "module": "chaosgcp.cloudrun.probes",
          "arguments": {
            "parent": "projects/reliably-staging-project/locations/europe-west1"
          }
        }
      }
    ],
    "version": "1.0.0",
    "controls": [
      {
        "name": "reliably",
        "provider": {
          "type": "python",
          "module": "chaosreliably.controls.experiment",
          "arguments": {
            "exp_id": "4556a14b-e776-4cd1-a6b1-c320e06bde2c",
            "org_id": "8f67bb6a-4944-40af-80b0-921023467cdc"
          }
        }
      }
    ],
    "description": "n/a",
    "contributions": {
      "security": "none",
      "performance": "none",
      "availability": "none"
    },
    "dry": null,
    "extensions": [
      {
        "name": "reliably",
        "pauses": [],
        "termination": null,
        "execution_url": "https://app.reliably.dev/executions/view/?id=8c9625ec-dce2-4c1b-998a-b53def2e7163&exp=4556a14b-e776-4cd1-a6b1-c320e06bde2c"
      }
    ]
  },
  "start": "2023-02-05T17:04:34.157959",
  "status": "completed",
  "deviated": false,
  "steady_states": {
    "before": null,
    "after": null,
    "during": []
  },
  "run": [
    {
      "activity": {
        "name": "list-cloudrun-instances",
        "type": "probe",
        "provider": {
          "func": "list_services",
          "type": "python",
          "module": "chaosgcp.cloudrun.probes",
          "arguments": {
            "parent": "projects/reliably-staging-project/locations/europe-west1"
          }
        },
        "_id": "df41ea0652af"
      },
      "output": null,
      "start": "2023-02-05T17:04:34.949019",
      "status": "failed",
      "exception": [
        "Traceback (most recent call last):\n",
        "  File \"/opt/hostedtoolcache/Python/3.10.9/x64/lib/python3.10/site-packages/chaoslib/provider/python.py\", line 56, in run_python_activity\n    return func(**arguments)\n",
        "  File \"/opt/hostedtoolcache/Python/3.10.9/x64/lib/python3.10/site-packages/chaosgcp/cloudrun/probes.py\", line 52, in list_services\n    credentials = load_credentials(secrets)\n",
        "  File \"/opt/hostedtoolcache/Python/3.10.9/x64/lib/python3.10/site-packages/chaosgcp/__init__.py\", line 190, in load_credentials\n    raise FailedActivity(\n",
        "chaoslib.exceptions.ActivityFailed: missing GCP credentials settings in secrets of this activity\n",
        "\nDuring handling of the above exception, another exception occurred:\n\n",
        "chaoslib.exceptions.ActivityFailed: chaoslib.exceptions.ActivityFailed: missing GCP credentials settings in secrets of this activity\n"
      ],
      "end": "2023-02-05T17:04:35.370710",
      "duration": 0.421691
    }
  ],
  "rollbacks": [],
  "end": "2023-02-05T17:04:35.679836",
  "duration": 1.5234699249267578
}